Traceback (most recent call last):
  File "C:\Users\Yuliceth Ramos\AppData\Roaming\Python\Python39\site-packages\nbclient\client.py", line 782, in _async_poll_for_reply
    msg = await ensure_async(self.kc.shell_channel.get_msg(timeout=new_timeout))
  File "C:\Users\Yuliceth Ramos\AppData\Roaming\Python\Python39\site-packages\jupyter_core\utils\__init__.py", line 198, in ensure_async
    result = await obj
  File "C:\Users\Yuliceth Ramos\AppData\Roaming\Python\Python39\site-packages\jupyter_client\channels.py", line 313, in get_msg
    raise Empty
_queue.Empty

During handling of the above exception, another exception occurred:

Traceback (most recent call last):
  File "C:\Users\Yuliceth Ramos\.conda\envs\ml-env\lib\site-packages\jupyter_cache\executors\utils.py", line 58, in single_nb_execution
    executenb(
  File "C:\Users\Yuliceth Ramos\AppData\Roaming\Python\Python39\site-packages\nbclient\client.py", line 1319, in execute
    return NotebookClient(nb=nb, resources=resources, km=km, **kwargs).execute()
  File "C:\Users\Yuliceth Ramos\AppData\Roaming\Python\Python39\site-packages\jupyter_core\utils\__init__.py", line 165, in wrapped
    return loop.run_until_complete(inner)
  File "C:\Users\Yuliceth Ramos\.conda\envs\ml-env\lib\asyncio\base_events.py", line 647, in run_until_complete
    return future.result()
  File "C:\Users\Yuliceth Ramos\AppData\Roaming\Python\Python39\site-packages\nbclient\client.py", line 709, in async_execute
    await self.async_execute_cell(
  File "C:\Users\Yuliceth Ramos\AppData\Roaming\Python\Python39\site-packages\nbclient\client.py", line 1005, in async_execute_cell
    exec_reply = await self.task_poll_for_reply
  File "C:\Users\Yuliceth Ramos\AppData\Roaming\Python\Python39\site-packages\nbclient\client.py", line 806, in _async_poll_for_reply
    error_on_timeout_execute_reply = await self._async_handle_timeout(timeout, cell)
  File "C:\Users\Yuliceth Ramos\AppData\Roaming\Python\Python39\site-packages\nbclient\client.py", line 856, in _async_handle_timeout
    raise CellTimeoutError.error_from_timeout_and_cell(
nbclient.exceptions.CellTimeoutError: A cell timed out while it was being executed, after 30 seconds.
The message was: Cell execution timed out.
Here is a preview of the cell contents:
-------------------
['from statsmodels.tsa.arima.model import ARIMA', '', '# Entrenar el modelo ARIMA para imputar los valores faltantes', "model = ARIMA(df_resampled['height'], order=(1, 1, 1))  # Se puede con diferentes valores de p, d, q", 'model_fit = model.fit()']
...
['# Imputar los valores faltantes con el modelo ARIMA', "df_resampled['height_imputed_arima'] = df_resampled['height'].fillna(model_fit.predict(start=0, end=len(df_resampled)-1))", '', '# Verificar que los datos faltantes han sido imputados', 'print(df_resampled.isnull().sum())  # Debería dar 0 si la imputación fue exitosa']
-------------------

